2017-05-23 20:35:54  INFO: Thread-1  login security decode failed
2017-05-23 20:35:54  WARNING: Thread-1  login security check failed, traceback: Traceback (most recent call last):
  File "./server.py", line 103, in CheckPassword
    if self.GetUser(decode_message[u'userName']).password == base64.b64decode(decode_message['password']):
UnboundLocalError: local variable 'decode_message' referenced before assignment

2017-05-23 20:35:54  ERROR: Thread-1  user server thread init failure
2017-05-23 20:40:28  INFO: Thread-1  login security decode failed
2017-05-23 20:40:28  WARNING: Thread-1  login security check failed, traceback: Traceback (most recent call last):
  File "./server.py", line 103, in CheckPassword
    if self.GetUser(decode_message[u'userName']).password == base64.b64decode(decode_message['password']):
UnboundLocalError: local variable 'decode_message' referenced before assignment

2017-05-23 20:41:18  ERROR: MainThread  port ERROR, traceback: Traceback (most recent call last):
  File "./server.py", line 162, in LoginServer
    loginServer = SocketServer.ThreadingTCPServer((LOGIN_HOST, LOGIN_PORT), self.LoginHandeler(self.CheckPassword, self.log.error))
  File "/usr/lib/python2.7/SocketServer.py", line 417, in __init__
    self.server_bind()
  File "/usr/lib/python2.7/SocketServer.py", line 431, in server_bind
    self.socket.bind(self.server_address)
  File "/usr/lib/python2.7/socket.py", line 228, in meth
    return getattr(self._sock,name)(*args)
error: [Errno 98] Address already in use

2017-05-23 20:41:52  INFO: Thread-1  login security decode failed
2017-05-23 20:41:52  WARNING: Thread-1  login security check failed, traceback: Traceback (most recent call last):
  File "./server.py", line 103, in CheckPassword
    if self.GetUser(decode_message[u'userName']).password == base64.b64decode(decode_message[u'password']):
UnboundLocalError: local variable 'decode_message' referenced before assignment

2017-05-23 20:44:33  INFO: Thread-1  login security decode failed
2017-05-23 20:44:33  WARNING: Thread-1  login security check failed, traceback: Traceback (most recent call last):
  File "./server.py", line 103, in CheckPassword
    if self.GetUser(decode_message[u'userName']).password == base64.b64decode(decode_message[u'password']):
UnboundLocalError: local variable 'decode_message' referenced before assignment

2017-05-23 20:50:53  INFO: Thread-1  login security decode failed
2017-05-23 20:50:53  WARNING: Thread-1  login security check failed, traceback: Traceback (most recent call last):
  File "./server.py", line 103, in CheckPassword
    if self.GetUser(decode_message[u'userName']).password == base64.b64decode(decode_message[u'password']):
UnboundLocalError: local variable 'decode_message' referenced before assignment

2017-05-23 20:52:28  ERROR: MainThread  port ERROR, traceback: Traceback (most recent call last):
  File "./server.py", line 162, in LoginServer
    loginServer = SocketServer.ThreadingTCPServer((LOGIN_HOST, LOGIN_PORT), self.LoginHandeler(self.CheckPassword, self.log.error))
  File "/usr/lib/python2.7/SocketServer.py", line 417, in __init__
    self.server_bind()
  File "/usr/lib/python2.7/SocketServer.py", line 431, in server_bind
    self.socket.bind(self.server_address)
  File "/usr/lib/python2.7/socket.py", line 228, in meth
    return getattr(self._sock,name)(*args)
error: [Errno 98] Address already in use

2017-05-23 20:52:54  INFO: Thread-1  login security decode failed
2017-05-23 20:52:54  WARNING: Thread-1  login security check failed, traceback: Traceback (most recent call last):
  File "./server.py", line 103, in CheckPassword
    if self.GetUser(decode_message[u'userName']).password == base64.b64decode(decode_message[u'password']):
UnboundLocalError: local variable 'decode_message' referenced before assignment

2017-05-23 20:54:00  INFO: Thread-1  login security decode failed
2017-05-23 20:54:00  WARNING: Thread-1  login security check failed, traceback: Traceback (most recent call last):
  File "./server.py", line 103, in CheckPassword
    if self.GetUser(decode_message[u'userName']).password == base64.b64decode(decode_message[u'password']):
UnboundLocalError: local variable 'decode_message' referenced before assignment

2017-05-23 20:54:51  ERROR: MainThread  port ERROR, traceback: Traceback (most recent call last):
  File "./server.py", line 163, in LoginServer
    loginServer = SocketServer.ThreadingTCPServer((LOGIN_HOST, LOGIN_PORT), self.LoginHandeler(self.CheckPassword, self.log.error))
  File "/usr/lib/python2.7/SocketServer.py", line 417, in __init__
    self.server_bind()
  File "/usr/lib/python2.7/SocketServer.py", line 431, in server_bind
    self.socket.bind(self.server_address)
  File "/usr/lib/python2.7/socket.py", line 228, in meth
    return getattr(self._sock,name)(*args)
error: [Errno 98] Address already in use

2017-05-23 20:55:09  INFO: Thread-1  login security decode failed
2017-05-23 20:55:09  WARNING: Thread-1  login security check failed, traceback: Traceback (most recent call last):
  File "./server.py", line 104, in CheckPassword
    if self.GetUser(decode_message[u'userName']).password == base64.b64decode(decode_message[u'password']):
UnboundLocalError: local variable 'decode_message' referenced before assignment

2017-05-23 20:55:30  ERROR: MainThread  port ERROR, traceback: Traceback (most recent call last):
  File "./server.py", line 163, in LoginServer
    loginServer = SocketServer.ThreadingTCPServer((LOGIN_HOST, LOGIN_PORT), self.LoginHandeler(self.CheckPassword, self.log.error))
  File "/usr/lib/python2.7/SocketServer.py", line 417, in __init__
    self.server_bind()
  File "/usr/lib/python2.7/SocketServer.py", line 431, in server_bind
    self.socket.bind(self.server_address)
  File "/usr/lib/python2.7/socket.py", line 228, in meth
    return getattr(self._sock,name)(*args)
error: [Errno 98] Address already in use

2017-05-23 20:55:39  ERROR: MainThread  port ERROR, traceback: Traceback (most recent call last):
  File "./server.py", line 163, in LoginServer
    loginServer = SocketServer.ThreadingTCPServer((LOGIN_HOST, LOGIN_PORT), self.LoginHandeler(self.CheckPassword, self.log.error))
  File "/usr/lib/python2.7/SocketServer.py", line 417, in __init__
    self.server_bind()
  File "/usr/lib/python2.7/SocketServer.py", line 431, in server_bind
    self.socket.bind(self.server_address)
  File "/usr/lib/python2.7/socket.py", line 228, in meth
    return getattr(self._sock,name)(*args)
error: [Errno 98] Address already in use

2017-05-23 20:56:05  ERROR: MainThread  port ERROR, traceback: Traceback (most recent call last):
  File "./server.py", line 163, in LoginServer
    loginServer = SocketServer.ThreadingTCPServer((LOGIN_HOST, LOGIN_PORT), self.LoginHandeler(self.CheckPassword, self.log.error))
  File "/usr/lib/python2.7/SocketServer.py", line 417, in __init__
    self.server_bind()
  File "/usr/lib/python2.7/SocketServer.py", line 431, in server_bind
    self.socket.bind(self.server_address)
  File "/usr/lib/python2.7/socket.py", line 228, in meth
    return getattr(self._sock,name)(*args)
error: [Errno 98] Address already in use

2017-05-23 20:58:20  INFO: Thread-1  login security decode failed
2017-05-23 20:58:20  WARNING: Thread-1  login security check failed, traceback: Traceback (most recent call last):
  File "./server.py", line 104, in CheckPassword
    if self.GetUser(decode_message[u'userName']).password == base64.b64decode(decode_message[u'password']):
UnboundLocalError: local variable 'decode_message' referenced before assignment

2017-05-23 21:00:26  INFO: Thread-1  login security decode failed
2017-05-23 21:00:26  WARNING: Thread-1  login security check failed, traceback: Traceback (most recent call last):
  File "./server.py", line 90, in CheckPassword
    if self.GetUser(decode_message[u'userName']).password == base64.b64decode(decode_message[u'password']):
UnboundLocalError: local variable 'decode_message' referenced before assignment

2017-05-23 21:01:05  ERROR: MainThread  port ERROR, traceback: Traceback (most recent call last):
  File "./server.py", line 150, in LoginServer
    loginServer = SocketServer.ThreadingTCPServer((LOGIN_HOST, LOGIN_PORT), self.LoginHandeler(self.CheckPassword, self.log.error))
  File "/usr/lib/python2.7/SocketServer.py", line 417, in __init__
    self.server_bind()
  File "/usr/lib/python2.7/SocketServer.py", line 431, in server_bind
    self.socket.bind(self.server_address)
  File "/usr/lib/python2.7/socket.py", line 228, in meth
    return getattr(self._sock,name)(*args)
error: [Errno 98] Address already in use

2017-05-23 21:02:17  INFO: Thread-1  new user: zero login success
2017-05-23 21:04:28  INFO: Thread-2  new user: zero login success
2017-05-23 21:05:26  INFO: Thread-3  new user: zero login success
2017-05-23 21:05:48  ERROR: MainThread  port ERROR, traceback: Traceback (most recent call last):
  File "./server.py", line 150, in LoginServer
    loginServer = SocketServer.ThreadingTCPServer((LOGIN_HOST, LOGIN_PORT), self.LoginHandeler(self.CheckPassword, self.log.error))
  File "/usr/lib/python2.7/SocketServer.py", line 417, in __init__
    self.server_bind()
  File "/usr/lib/python2.7/SocketServer.py", line 431, in server_bind
    self.socket.bind(self.server_address)
  File "/usr/lib/python2.7/socket.py", line 228, in meth
    return getattr(self._sock,name)(*args)
error: [Errno 98] Address already in use

2017-05-23 21:06:36  INFO: Thread-1  new user: zero login success
2017-05-23 21:10:50  INFO: Thread-2  login security decode failed
2017-05-23 21:10:50  WARNING: Thread-2  login security check failed, traceback: Traceback (most recent call last):
  File "./server.py", line 91, in CheckPassword
    if self.GetUser(decode_message[u'userName']).password == base64.b64decode(decode_message[u'password']):
UnboundLocalError: local variable 'decode_message' referenced before assignment

2017-05-23 21:13:58  INFO: Thread-3  login security decode failed
2017-05-23 21:13:58  WARNING: Thread-3  login security check failed, traceback: Traceback (most recent call last):
  File "./server.py", line 91, in CheckPassword
    if self.GetUser(decode_message[u'userName']).password == base64.b64decode(decode_message[u'password']):
UnboundLocalError: local variable 'decode_message' referenced before assignment

2017-05-23 21:18:11  INFO: Thread-1  new user: zero login success
2017-05-23 21:18:45  WARNING: Thread-2  login security check failed, traceback: Traceback (most recent call last):
  File "./server.py", line 91, in CheckPassword
    if self.GetUser(decode_message[u'userName']).password == base64.b64decode(decode_message[u'password']):
KeyError: u'userName'

2017-05-23 21:21:20  WARNING: Thread-1  login security check failed, traceback: Traceback (most recent call last):
  File "./server.py", line 91, in CheckPassword
    if self.GetUser(decode_message[u'name']).password == base64.b64decode(decode_message[u'password']):
KeyError: u'name'

2017-05-23 21:22:37  INFO: Thread-1  new user: zero login success
2017-05-23 21:22:58  INFO: Thread-2  new user: zero login success
2017-05-23 21:41:09  INFO: Thread-1  new user: zero login success
2017-05-23 21:41:46  INFO: Thread-2  new user: zero login success
2017-05-23 21:43:23  INFO: Thread-3  new user: zero login success
2017-05-23 21:43:43  INFO: Thread-4  new user: zero login success
2017-05-23 21:54:17  INFO: Thread-1  new user: zero login success
2017-05-23 22:04:02  INFO: Thread-2  new user: zero login success
2017-05-23 22:17:42  INFO: Thread-3  new user: zero login success
2017-05-23 22:29:59  INFO: Thread-1  new user: zero login success
2017-05-23 22:30:03  INFO: Thread-2  new user: zero login success
2017-05-23 22:32:13  INFO: Thread-1  new user: zero login success
2017-05-23 22:32:31  INFO: Thread-2  new user: zero login success
2017-05-23 22:33:48  INFO: Thread-3  new user: zero login success
2017-05-23 22:35:33  INFO: Thread-1  new user: zero login success
2017-05-23 22:35:47  INFO: Thread-2  new user: zero login success
2017-05-23 22:36:59  INFO: Thread-3  new user: zero login success
2017-05-23 22:37:32  INFO: Thread-4  new user: zero login success
2017-05-23 22:40:06  INFO: Thread-5  new user: zero login success
2017-05-23 22:41:13  ERROR: MainThread  port ERROR, traceback: Traceback (most recent call last):
  File "./server.py", line 151, in LoginServer
    loginServer = SocketServer.ThreadingTCPServer((LOGIN_HOST, LOGIN_PORT), self.LoginHandeler(self.CheckPassword, self.log.error))
  File "/usr/lib/python2.7/SocketServer.py", line 417, in __init__
    self.server_bind()
  File "/usr/lib/python2.7/SocketServer.py", line 431, in server_bind
    self.socket.bind(self.server_address)
  File "/usr/lib/python2.7/socket.py", line 228, in meth
    return getattr(self._sock,name)(*args)
error: [Errno 98] Address already in use

2017-05-23 22:41:26  INFO: Thread-1  new user: zero login success
2017-05-23 22:41:58  INFO: Thread-2  new user: zero login success
2017-05-23 22:46:03  INFO: Thread-3  new user: zero login success
2017-05-23 22:52:27  ERROR: MainThread  port ERROR, traceback: Traceback (most recent call last):
  File "./server.py", line 155, in LoginServer
    loginServer.serve_forever()
  File "/usr/lib/python2.7/SocketServer.py", line 231, in serve_forever
    poll_interval)
  File "/usr/lib/python2.7/SocketServer.py", line 150, in _eintr_retry
    return func(*args)
KeyboardInterrupt

2017-05-23 22:54:31  INFO: Thread-1  new user: zero login success
2017-05-23 22:54:43  INFO: Thread-2  new user: zero login success
2017-05-23 22:55:08  INFO: Thread-3  new user: zero login success
2017-05-23 22:55:47  INFO: Thread-4  new user: zero login success
2017-05-23 22:56:29  INFO: Thread-5  new user: zero login success
2017-05-23 23:06:43  ERROR: MainThread  port ERROR, traceback: Traceback (most recent call last):
  File "./server.py", line 151, in LoginServer
    loginServer = SocketServer.ThreadingTCPServer((LOGIN_HOST, LOGIN_PORT), self.LoginHandeler(self.CheckPassword, self.log.error))
  File "/usr/lib/python2.7/SocketServer.py", line 417, in __init__
    self.server_bind()
  File "/usr/lib/python2.7/SocketServer.py", line 431, in server_bind
    self.socket.bind(self.server_address)
  File "/usr/lib/python2.7/socket.py", line 228, in meth
    return getattr(self._sock,name)(*args)
error: [Errno 98] Address already in use

2017-05-23 23:07:48  INFO: Thread-1  new user: zero login success
2017-05-23 23:07:58  INFO: Thread-2  new user: zero login success
2017-05-23 23:10:10  INFO: Thread-1  new user: zero login success
2017-05-23 23:10:36  INFO: Thread-2  new user: zero login success
2017-05-23 23:11:45  INFO: Thread-3  new user: zero login success
2017-05-23 23:18:17  INFO: Thread-1  new user: zero login success
2017-05-23 23:18:35  INFO: Thread-2  new user: zero login success
2017-05-23 23:21:06  INFO: Thread-3  new user: zero login success
2017-05-23 23:23:10  INFO: Thread-4  new user: zero login success
2017-05-23 23:23:45  INFO: Thread-5  new user: zero login success
