2017-06-09 19:44:48  ERROR: Thread-1  DataBase error: Traceback (most recent call last):
  File "K:\ºóÌ¨\game\game\data.py", line 24, in GetUserInfo
    tmp = users.find_one({u'name':user_name})
  File "D:\Python27\lib\site-packages\pymongo\collection.py", line 1102, in find_one
    for result in cursor.limit(-1):
  File "D:\Python27\lib\site-packages\pymongo\cursor.py", line 1114, in next
    if len(self.__data) or self._refresh():
  File "D:\Python27\lib\site-packages\pymongo\cursor.py", line 1036, in _refresh
    self.__collation))
  File "D:\Python27\lib\site-packages\pymongo\cursor.py", line 928, in __send_message
    helpers._check_command_response(doc['data'][0])
  File "D:\Python27\lib\site-packages\pymongo\helpers.py", line 210, in _check_command_response
    raise OperationFailure(msg % errmsg, code, response)
OperationFailure: not authorized on game to execute command { find: "users", filter: { name: "zero" }, limit: 1, singleBatch: true }

2017-06-09 19:44:48  INFO: Thread-1  user zero login with wrong password
2017-06-09 19:46:58  INFO: Thread-1  new user: zero login success
2017-06-09 19:51:09  INFO: Thread-1  new user: zero login success
2017-06-09 21:44:30  INFO: Thread-1  new user: zero login success
2017-06-09 21:54:27  INFO: Thread-1  new user: zero login success
2017-06-09 23:01:05  INFO: Thread-1  new user: zero login success
