2017-05-19 18:01:37  ERROR: MainThread  what
2017-05-19 18:01:37  DEBUG: MainThread  hello
2017-05-19 20:44:50  ERROR: MainThread  what
2017-05-19 20:44:50  DEBUG: MainThread  hello
2017-05-20 02:26:36  INFO: MainThread  new user: zero login success
2017-05-20 02:30:46  ERROR: MainThread  port ERROR, traceback: Traceback (most recent call last):
  File "./server.py", line 132, in LoginServer
    loginServer = SocketServer.TCPServer((LOGIN_HOST, LOGIN_PORT), self.LoginHandeler(self.CheckPassword, self.log.error))
AttributeError: 'users' object has no attribute 'log'

2017-05-20 02:31:02  ERROR: MainThread  port ERROR, traceback: Traceback (most recent call last):
  File "./server.py", line 132, in LoginServer
    loginServer = SocketServer.TCPServer((LOGIN_HOST, LOGIN_PORT), self.LoginHandeler(self.CheckPassword, self.log.error))
AttributeError: 'users' object has no attribute 'log'

2017-05-20 02:31:46  INFO: MainThread  new user: zero login success
2017-05-20 02:31:46  WARNING: MainThread  login security check failed, traceback: Traceback (most recent call last):
  File "./server.py", line 86, in CheckPassword
    token,signature = self.sec.Encrypt(tokenID)
AttributeError: 'users' object has no attribute 'sec'

2017-05-20 02:32:24  ERROR: MainThread  port ERROR, traceback: Traceback (most recent call last):
  File "./server.py", line 132, in LoginServer
    loginServer = SocketServer.TCPServer((LOGIN_HOST, LOGIN_PORT), self.LoginHandeler(self.CheckPassword, self.log.error))
  File "/usr/lib/python2.7/SocketServer.py", line 417, in __init__
    self.server_bind()
  File "/usr/lib/python2.7/SocketServer.py", line 431, in server_bind
    self.socket.bind(self.server_address)
  File "/usr/lib/python2.7/socket.py", line 228, in meth
    return getattr(self._sock,name)(*args)
error: [Errno 98] Address already in use

2017-05-20 02:32:36  ERROR: MainThread  port ERROR, traceback: Traceback (most recent call last):
  File "./server.py", line 132, in LoginServer
    loginServer = SocketServer.TCPServer((LOGIN_HOST, LOGIN_PORT), self.LoginHandeler(self.CheckPassword, self.log.error))
  File "/usr/lib/python2.7/SocketServer.py", line 417, in __init__
    self.server_bind()
  File "/usr/lib/python2.7/SocketServer.py", line 431, in server_bind
    self.socket.bind(self.server_address)
  File "/usr/lib/python2.7/socket.py", line 228, in meth
    return getattr(self._sock,name)(*args)
error: [Errno 98] Address already in use

2017-05-20 02:57:56  INFO: MainThread  new user: zero login success
2017-05-20 16:47:15  ERROR: MainThread  port ERROR, traceback: Traceback (most recent call last):
  File "./server.py", line 123, in LoginServer
    loginServer = SocketServer.TCPServer((LOGIN_HOST, LOGIN_PORT), self.LoginHandeler(self.CheckPassword, self.log.error))
  File "/usr/lib/python2.7/SocketServer.py", line 417, in __init__
    self.server_bind()
  File "/usr/lib/python2.7/SocketServer.py", line 431, in server_bind
    self.socket.bind(self.server_address)
  File "/usr/lib/python2.7/socket.py", line 228, in meth
    return getattr(self._sock,name)(*args)
error: [Errno 98] Address already in use

2017-05-20 16:48:31  INFO: MainThread  new user: zero login success
2017-05-20 17:36:35  INFO: MainThread  login security decode failed
2017-05-20 17:36:35  WARNING: MainThread  login security check failed, traceback: Traceback (most recent call last):
  File "./server.py", line 80, in CheckPassword
    def HandlerActionMsg(self, token):
UnboundLocalError: local variable 'decode_message' referenced before assignment

2017-05-20 17:50:40  ERROR: MainThread  port ERROR, traceback: Traceback (most recent call last):
  File "./server.py", line 157, in LoginServer
    loginServer = SocketServer.ThreadingTCPServer((LOGIN_HOST, LOGIN_PORT), self.LoginHandeler(self.CheckPassword, self.log.error))
  File "/usr/lib/python2.7/SocketServer.py", line 417, in __init__
    self.server_bind()
  File "/usr/lib/python2.7/SocketServer.py", line 431, in server_bind
    self.socket.bind(self.server_address)
  File "/usr/lib/python2.7/socket.py", line 228, in meth
    return getattr(self._sock,name)(*args)
error: [Errno 98] Address already in use

2017-05-20 17:54:55  INFO: Thread-1  new user: zero login success
